Workbook

Sheet LEIA-ME
B2: Análise Crítica · TIROL
B3: Dados fictícios: construtora inventada de Natal/RN, portfólio Vizu Dados.
B4: Uma aba por mês (MMMAA). Os campos são lidos pelo rótulo da coluna B.
B5: Versão 01 da planilha: a dívida da obra (item 10) desconta do resultado.

Sheet FEV26
B2: ANÁLISE DE DESEMPENHO ECONÔMICO DA OBRA
B3: Construtora fictícia de Natal/RN · portfólio Vizu Dados · dados inventados
B4: Versão 01 · revisão de 01/09/2025: a dívida da obra passa a descontar do resultado
B18: Célula editável
B19: Resultado (não editar)
B20: Tabela anexada
B21: % relacionada
B24: 1º passo: Projeto (definir o empreendimento) | D24: TIROL
B26: 2º passo: Mês de análise (definir o mês de referência) | E26: 46054
B28: 3º passo: Orçamento da obra projetado (com INCC no a realizar) | J28: 30119500
B29: Tipo do orçamento | J29: Orçamento legal
B31: 4º passo: Previsto do mês (incluir o % do cronograma) | F31: 0.0025
B33: 5º passo: Executado do mês (incluir o % medido) | F33: 0.0014
B35: 6º passo: Previsto acumulado do mês | F35: 0.0025
B37: 7º passo: Executado acumulado do mês | F37: 0.0014
B39: 8º passo: Crédito do orçamento (executado acumulado × orçamento) | F39: =F37*J28 -> 42167.3
B41: 8º passo (cont.): Saldo de contrato (tabela) | F41: =E74 -> 0
B43: 9º passo: Adiantamento de serviços não medidos (tabela) | F43: =E88 -> 0
B45: 10º passo: Adiantamento de materiais não estocados (tabela) | F45: =J74 -> 0
B47: 11º passo: Estoque de materiais (almoxarifado) | F47: =J88 -> 30119.5
B49: 12º passo: Equipamentos comprados (valor de mercado) | F49: =E102 -> 76300
B51: 13º passo: Receitas de personalizações (tabela) | F51: =J102 -> 0
B53: 14º passo: Contas a pagar dos medidos (relatório a pagar) | F53: =E115 -> 20000
B55: 15º passo: Valor desembolsado pela obra (relatório conferido) | F55: 51869.3
B56: Valor corrigido (sem os itens apontados irregularmente) | F56: =F55-J115 -> 51869.3
B58: 16º passo: Dívida da obra a ser paga (outra obra da carteira) | F58: =E129 -> 0
B63: Saldo de contrato | G63: Adiantamento de materiais não estocados
B74: Total | E74: =SUM(E64:E73) -> 0 | G74: Total | J74: =SUM(J64:J73) -> 0
B77: Adiantamento de serviços não medidos | G77: Estoque de materiais
G78: Material de canteiro (tapumes e contêineres) | J78: 10970.74
G79: Cimento e agregados | J79: 6700.22
G80: Aço CA-50 para fundação | J80: 12448.54
B88: Total | E88: =SUM(E78:E87) -> 0 | G88: Total | J88: =SUM(J78:J87) -> 30119.5
B91: Equipamentos comprados | G91: Receitas de personalizações
B92: Betoneira 400 L | E92: 9800
B93: Guincho de coluna | E93: 38500
B94: Container escritório (2 un.) | E94: 28000
B102: Total | E102: =SUM(E92:E101) -> 76300 | G102: Total | J102: =SUM(J92:J101) -> 0
B105: Contas a pagar dos medidos | G105: Itens apontados irregularmente no relatório
B106: Medição de terraplenagem · NF 12007 | E106: 5769.67
...

Sheet MAR26
B2: ANÁLISE DE DESEMPENHO ECONÔMICO DA OBRA
B3: Construtora fictícia de Natal/RN · portfólio Vizu Dados · dados inventados
B4: Versão 01 · revisão de 01/09/2025: a dívida da obra passa a descontar do resultado
B18: Célula editável
B19: Resultado (não editar)
B20: Tabela anexada
B21: % relacionada
B24: 1º passo: Projeto (definir o empreendimento) | D24: TIROL
B26: 2º passo: Mês de análise (definir o mês de referência) | E26: 46082
B28: 3º passo: Orçamento da obra projetado (com INCC no a realizar) | J28: 30243400
B29: Tipo do orçamento | J29: Orçamento legal
B31: 4º passo: Previsto do mês (incluir o % do cronograma) | F31: 0.0075
B33: 5º passo: Executado do mês (incluir o % medido) | F33: 0.0043
B35: 6º passo: Previsto acumulado do mês | F35: 0.01
B37: 7º passo: Executado acumulado do mês | F37: 0.0057
B39: 8º passo: Crédito do orçamento (executado acumulado × orçamento) | F39: =F37*J28 -> 172387.38
B41: 8º passo (cont.): Saldo de contrato (tabela) | F41: =E74 -> 0
B43: 9º passo: Adiantamento de serviços não medidos (tabela) | F43: =E88 -> 0
B45: 10º passo: Adiantamento de materiais não estocados (tabela) | F45: =J74 -> 0
B47: 11º passo: Estoque de materiais (almoxarifado) | F47: =J88 -> 61094.2
B49: 12º passo: Equipamentos comprados (valor de mercado) | F49: =E102 -> 76300
B51: 13º passo: Receitas de personalizações (tabela) | F51: =J102 -> 0
B53: 14º passo: Contas a pagar dos medidos (relatório a pagar) | F53: =E115 -> 31554.1
B55: 15º passo: Valor desembolsado pela obra (relatório conferido) | F55: 200559.33
B56: Valor corrigido (sem os itens apontados irregularmente) | F56: =F55-J115 -> 200559.33
B58: 16º passo: Dívida da obra a ser paga (outra obra da carteira) | F58: =E129 -> 0
B63: Saldo de contrato | G63: Adiantamento de materiais não estocados
B74: Total | E74: =SUM(E64:E73) -> 0 | G74: Total | J74: =SUM(J64:J73) -> 0
B77: Adiantamento de serviços não medidos | G77: Estoque de materiais
G78: Material de canteiro (tapumes e contêineres) | J78: 22941.39
G79: Cimento e agregados | J79: 14685.39
G80: Aço CA-50 para fundação | J80: 23467.42
B88: Total | E88: =SUM(E78:E87) -> 0 | G88: Total | J88: =SUM(J78:J87) -> 61094.2
B91: Equipamentos comprados | G91: Receitas de personalizações
B92: Betoneira 400 L | E92: 9800
B93: Guincho de coluna | E93: 38500
B94: Container escritório (2 un.) | E94: 28000
B102: Total | E102: =SUM(E92:E101) -> 76300 | G102: Total | J102: =SUM(J92:J101) -> 0
B105: Contas a pagar dos medidos | G105: Itens apontados irregularmente no relatório
B106: Medição de terraplenagem · NF 77565 | E106: 7639.46
...

Sheet ABR26
B2: ANÁLISE DE DESEMPENHO ECONÔMICO DA OBRA
B3: Construtora fictícia de Natal/RN · portfólio Vizu Dados · dados inventados
B4: Versão 01 · revisão de 01/09/2025: a dívida da obra passa a descontar do resultado
B18: Célula editável
B19: Resultado (não editar)
B20: Tabela anexada
B21: % relacionada
B24: 1º passo: Projeto (definir o empreendimento) | D24: TIROL
B26: 2º passo: Mês de análise (definir o mês de referência) | E26: 46082
B28: 3º passo: Orçamento da obra projetado (com INCC no a realizar) | J28: 30367300
B29: Tipo do orçamento | J29: Orçamento legal
B31: 4º passo: Previsto do mês (incluir o % do cronograma) | F31: 0.012
B33: 5º passo: Executado do mês (incluir o % medido) | F33: 0.0057
B35: 6º passo: Previsto acumulado do mês | F35: 0.022
B37: 7º passo: Executado acumulado do mês | F37: 0.0114
B39: 8º passo: Crédito do orçamento (executado acumulado × orçamento) | F39: =F37*J28 -> 346187.22
B41: 8º passo (cont.): Saldo de contrato (tabela) | F41: =E74 -> 0
B43: 9º passo: Adiantamento de serviços não medidos (tabela) | F43: =E88 -> 0
B45: 10º passo: Adiantamento de materiais não estocados (tabela) | F45: =J74 -> 0
B47: 11º passo: Estoque de materiais (almoxarifado) | F47: =J88 -> 51092.5
B49: 12º passo: Equipamentos comprados (valor de mercado) | F49: =E102 -> 76300
B51: 13º passo: Receitas de personalizações (tabela) | F51: =J102 -> 0
B53: 14º passo: Contas a pagar dos medidos (relatório a pagar) | F53: =E115 -> 34905.3
B55: 15º passo: Valor desembolsado pela obra (relatório conferido) | F55: 360309.69
B56: Valor corrigido (sem os itens apontados irregularmente) | F56: =F55-J115 -> 360309.69
B58: 16º passo: Dívida da obra a ser paga (outra obra da carteira) | F58: =E129 -> 0
B63: Saldo de contrato | G63: Adiantamento de materiais não estocados
B74: Total | E74: =SUM(E64:E73) -> 0 | G74: Total | J74: =SUM(J64:J73) -> 0
B77: Adiantamento de serviços não medidos | G77: Estoque de materiais
G78: Material de canteiro (tapumes e contêineres) | J78: 14244.22
G79: Cimento e agregados | J79: 18308.45
G80: Aço CA-50 para fundação | J80: 18539.83
B88: Total | E88: =SUM(E78:E87) -> 0 | G88: Total | J88: =SUM(J78:J87) -> 51092.5
B91: Equipamentos comprados | G91: Receitas de personalizações
B92: Betoneira 400 L | E92: 9800
B93: Guincho de coluna | E93: 38500
B94: Container escritório (2 un.) | E94: 28000
B102: Total | E102: =SUM(E92:E101) -> 76300 | G102: Total | J102: =SUM(J92:J101) -> 0
B105: Contas a pagar dos medidos | G105: Itens apontados irregularmente no relatório
B106: Medição de terraplenagem · NF 73503 | E106: 9136.13
...

Sheet MAI26
B2: ANÁLISE DE DESEMPENHO ECONÔMICO DA OBRA
B3: Construtora fictícia de Natal/RN · portfólio Vizu Dados · dados inventados
B4: Versão 01 · revisão de 01/09/2025: a dívida da obra passa a descontar do resultado
B18: Célula editável
B19: Resultado (não editar)
B20: Tabela anexada
B21: % relacionada
B24: 1º passo: Projeto (definir o empreendimento) | D24: TIROL
B26: 2º passo: Mês de análise (definir o mês de referência) | E26: 46143
B28: 3º passo: Orçamento da obra projetado (com INCC no a realizar) | J28: 30491200
B29: Tipo do orçamento | J29: Orçamento legal
B31: 4º passo: Previsto do mês (incluir o % do cronograma) | F31: 0.0163
B33: 5º passo: Executado do mês (incluir o % medido) | F33: 0.0082
B35: 6º passo: Previsto acumulado do mês | F35: 0.0383
B37: 7º passo: Executado acumulado do mês | F37: 0.0196
B39: 8º passo: Crédito do orçamento (executado acumulado × orçamento) | F39: =F37*J28 -> 597627.52
B41: 8º passo (cont.): Saldo de contrato (tabela) | F41: =E74 -> 0
B43: 9º passo: Adiantamento de serviços não medidos (tabela) | F43: =E88 -> 0
B45: 10º passo: Adiantamento de materiais não estocados (tabela) | F45: =J74 -> 0
B47: 11º passo: Estoque de materiais (almoxarifado) | F47: =J88 -> 69381.89
B49: 12º passo: Equipamentos comprados (valor de mercado) | F49: =E102 -> 76300
B51: 13º passo: Receitas de personalizações (tabela) | F51: =J102 -> 0
B53: 14º passo: Contas a pagar dos medidos (relatório a pagar) | F53: =E115 -> 46452.66
B55: 15º passo: Valor desembolsado pela obra (relatório conferido) | F55: 618175.76
B56: Valor corrigido (sem os itens apontados irregularmente) | F56: =F55-J115 -> 618175.76
B58: 16º passo: Dívida da obra a ser paga (outra obra da carteira) | F58: =E129 -> 0
B63: Saldo de contrato | G63: Adiantamento de materiais não estocados
B74: Total | E74: =SUM(E64:E73) -> 0 | G74: Total | J74: =SUM(J64:J73) -> 0
B77: Adiantamento de serviços não medidos | G77: Estoque de materiais
G78: Material de canteiro (tapumes e contêineres) | J78: 17957.98
G79: Cimento e agregados | J79: 32137.4
G80: Aço CA-50 para fundação | J80: 19286.51
B88: Total | E88: =SUM(E78:E87) -> 0 | G88: Total | J88: =SUM(J78:J87) -> 69381.89
B91: Equipamentos comprados | G91: Receitas de personalizações
B92: Betoneira 400 L | E92: 9800
B93: Guincho de coluna | E93: 38500
B94: Container escritório (2 un.) | E94: 28000
B102: Total | E102: =SUM(E92:E101) -> 76300 | G102: Total | J102: =SUM(J92:J101) -> 0
B105: Contas a pagar dos medidos | G105: Itens apontados irregularmente no relatório
B106: Medição de terraplenagem · NF 28131 | E106: 15519.77
...

Sheet JUN26
B2: ANÁLISE DE DESEMPENHO ECONÔMICO DA OBRA
B3: Construtora fictícia de Natal/RN · portfólio Vizu Dados · dados inventados
B4: Versão 01 · revisão de 01/09/2025: a dívida da obra passa a descontar do resultado
B18: Célula editável
B19: Resultado (não editar)
B20: Tabela anexada
B21: % relacionada
B24: 1º passo: Projeto (definir o empreendimento) | D24: TIROL
B26: 2º passo: Mês de análise (definir o mês de referência) | E26: 46174
B28: 3º passo: Orçamento da obra projetado (com INCC no a realizar) | J28: 30615100
B29: Tipo do orçamento | J29: Orçamento legal
B31: 4º passo: Previsto do mês (incluir o % do cronograma) | F31: 0.0202
B33: 5º passo: Executado do mês (incluir o % medido) | F33: 0.0109
B35: 6º passo: Previsto acumulado do mês | F35: 0.0585
B37: 7º passo: Executado acumulado do mês | F37: 0.0305
B39: 8º passo: Crédito do orçamento (executado acumulado × orçamento) | F39: =F37*J28 -> 933760.55
B41: 8º passo (cont.): Saldo de contrato (tabela) | F41: =E74 -> 0
B43: 9º passo: Adiantamento de serviços não medidos (tabela) | F43: =E88 -> 0
B45: 10º passo: Adiantamento de materiais não estocados (tabela) | F45: =J74 -> 0
B47: 11º passo: Estoque de materiais (almoxarifado) | F47: =J88 -> 52207.08
B49: 12º passo: Equipamentos comprados (valor de mercado) | F49: =E102 -> 76300
B51: 13º passo: Receitas de personalizações (tabela) | F51: =J102 -> 0
B53: 14º passo: Contas a pagar dos medidos (relatório a pagar) | F53: =E115 -> 61769.32
B55: 15º passo: Valor desembolsado pela obra (relatório conferido) | F55: 919552.74
B56: Valor corrigido (sem os itens apontados irregularmente) | F56: =F55-J115 -> 919552.74
B58: 16º passo: Dívida da obra a ser paga (outra obra da carteira) | F58: =E129 -> 0
B63: Saldo de contrato | G63: Adiantamento de materiais não estocados
B74: Total | E74: =SUM(E64:E73) -> 0 | G74: Total | J74: =SUM(J64:J73) -> 0
B77: Adiantamento de serviços não medidos | G77: Estoque de materiais
G78: Material de canteiro (tapumes e contêineres) | J78: 15852.21
G79: Cimento e agregados | J79: 18350.43
G80: Aço CA-50 para fundação | J80: 18004.44
B88: Total | E88: =SUM(E78:E87) -> 0 | G88: Total | J88: =SUM(J78:J87) -> 52207.08
B91: Equipamentos comprados | G91: Receitas de personalizações
B92: Betoneira 400 L | E92: 9800
B93: Guincho de coluna | E93: 38500
B94: Container escritório (2 un.) | E94: 28000
B102: Total | E102: =SUM(E92:E101) -> 76300 | G102: Total | J102: =SUM(J92:J101) -> 0
B105: Contas a pagar dos medidos | G105: Itens apontados irregularmente no relatório
B106: Medição de terraplenagem · NF 41637 | E106: 17974.73
...

Sheet JUL26
B2: ANÁLISE DE DESEMPENHO ECONÔMICO DA OBRA
B3: Construtora fictícia de Natal/RN · portfólio Vizu Dados · dados inventados
B4: Versão 01 · revisão de 01/09/2025: a dívida da obra passa a descontar do resultado
B18: Célula editável
B19: Resultado (não editar)
B20: Tabela anexada
B21: % relacionada
B24: 1º passo: Projeto (definir o empreendimento) | D24: TIROL
B26: 2º passo: Mês de análise (definir o mês de referência) | E26: 46204
B28: 3º passo: Orçamento da obra projetado (com INCC no a realizar) | J28: 30739000
B29: Tipo do orçamento | J29: Orçamento legal
B31: 4º passo: Previsto do mês (incluir o % do cronograma) | F31: 0.0239
B33: 5º passo: Executado do mês (incluir o % medido) | F33: 0.014
B35: 6º passo: Previsto acumulado do mês | F35: 0.0824
B37: 7º passo: Executado acumulado do mês | F37: 0.0445
B39: 8º passo: Crédito do orçamento (executado acumulado × orçamento) | F39: =F37*J28 -> 1367885.5
B41: 8º passo (cont.): Saldo de contrato (tabela) | F41: =E74 -> 0
B43: 9º passo: Adiantamento de serviços não medidos (tabela) | F43: =E88 -> 0
B45: 10º passo: Adiantamento de materiais não estocados (tabela) | F45: =J74 -> 0
B47: 11º passo: Estoque de materiais (almoxarifado) | F47: =J88 -> 72027.41
B49: 12º passo: Equipamentos comprados (valor de mercado) | F49: =E102 -> 76300
B51: 13º passo: Receitas de personalizações (tabela) | F51: =J102 -> 0
B53: 14º passo: Contas a pagar dos medidos (relatório a pagar) | F53: =E115 -> 76291.84
B55: 15º passo: Valor desembolsado pela obra (relatório conferido) | F55: 1355462.7
B56: Valor corrigido (sem os itens apontados irregularmente) | F56: =F55-J115 -> 1355462.7
B58: 16º passo: Dívida da obra a ser paga (outra obra da carteira) | F58: =E129 -> 0
B63: Saldo de contrato | G63: Adiantamento de materiais não estocados
B74: Total | E74: =SUM(E64:E73) -> 0 | G74: Total | J74: =SUM(J64:J73) -> 0
B77: Adiantamento de serviços não medidos | G77: Estoque de materiais
G78: Material de canteiro (tapumes e contêineres) | J78: 33436.14
G79: Cimento e agregados | J79: 22338.31
G80: Aço CA-50 para fundação | J80: 16252.96
B88: Total | E88: =SUM(E78:E87) -> 0 | G88: Total | J88: =SUM(J78:J87) -> 72027.41
B91: Equipamentos comprados | G91: Receitas de personalizações
B92: Betoneira 400 L | E92: 9800
B93: Guincho de coluna | E93: 38500
B94: Container escritório (2 un.) | E94: 28000
B102: Total | E102: =SUM(E92:E101) -> 76300 | G102: Total | J102: =SUM(J92:J101) -> 0
B105: Contas a pagar dos medidos | G105: Itens apontados irregularmente no relatório
B106: Medição de terraplenagem · NF 61117 | E106: 26103.05
...

Sheet AGO26
B2: ANÁLISE DE DESEMPENHO ECONÔMICO DA OBRA
B3: Construtora fictícia de Natal/RN · portfólio Vizu Dados · dados inventados
B4: Versão 01 · revisão de 01/09/2025: a dívida da obra passa a descontar do resultado
B18: Célula editável
B19: Resultado (não editar)
B20: Tabela anexada
B21: % relacionada
B24: 1º passo: Projeto (definir o empreendimento) | D24: TIROL
B26: 2º passo: Mês de análise (definir o mês de referência) | E26: 46235
B28: 3º passo: Orçamento da obra projetado (com INCC no a realizar) | J28: 30862900
B29: Tipo do orçamento | J29: Orçamento legal
B31: 4º passo: Previsto do mês (incluir o % do cronograma) | F31: 0.0273
B33: 5º passo: Executado do mês (incluir o % medido) | F33: 0.0305
B35: 6º passo: Previsto acumulado do mês | F35: 0.1097
B37: 7º passo: Executado acumulado do mês | F37: 0.075
B39: 8º passo: Crédito do orçamento (executado acumulado × orçamento) | F39: =F37*J28 -> 2314717.5
B41: 8º passo (cont.): Saldo de contrato (tabela) | F41: =E74 -> 0
B43: 9º passo: Adiantamento de serviços não medidos (tabela) | F43: =E88 -> 0
B45: 10º passo: Adiantamento de materiais não estocados (tabela) | F45: =J74 -> 0
B47: 11º passo: Estoque de materiais (almoxarifado) | F47: =J88 -> 124014.79
B49: 12º passo: Equipamentos comprados (valor de mercado) | F49: =E102 -> 76300
B51: 13º passo: Receitas de personalizações (tabela) | F51: =J102 -> 0
B53: 14º passo: Contas a pagar dos medidos (relatório a pagar) | F53: =E115 -> 222069.64
B55: 15º passo: Valor desembolsado pela obra (relatório conferido) | F55: 2200572.3
B56: Valor corrigido (sem os itens apontados irregularmente) | F56: =F55-J115 -> 2200572.3
B58: 16º passo: Dívida da obra a ser paga (outra obra da carteira) | F58: =E129 -> 0
B63: Saldo de contrato | G63: Adiantamento de materiais não estocados
B74: Total | E74: =SUM(E64:E73) -> 0 | G74: Total | J74: =SUM(J64:J73) -> 0
B77: Adiantamento de serviços não medidos | G77: Estoque de materiais
G78: Aço CA-50 para blocos e baldrame | J78: 33997.89
G79: Cimento e agregados | J79: 45101.03
G80: Madeira para formas | J80: 44915.87
B88: Total | E88: =SUM(E78:E87) -> 0 | G88: Total | J88: =SUM(J78:J87) -> 124014.79
B91: Equipamentos comprados | G91: Receitas de personalizações
B92: Betoneira 400 L | E92: 9800
B93: Guincho de coluna | E93: 38500
B94: Container escritório (2 un.) | E94: 28000
B102: Total | E102: =SUM(E92:E101) -> 76300 | G102: Total | J102: =SUM(J92:J101) -> 0
B105: Contas a pagar dos medidos | G105: Itens apontados irregularmente no relatório
B106: Medição de fundação (estacas hélice) · NF 35049 | E106: 75849
...

Sheet SET26
B2: ANÁLISE DE DESEMPENHO ECONÔMICO DA OBRA
B3: Construtora fictícia de Natal/RN · portfólio Vizu Dados · dados inventados
B4: Versão 01 · revisão de 01/09/2025: a dívida da obra passa a descontar do resultado
B18: Célula editável
B19: Resultado (não editar)
B20: Tabela anexada
B21: % relacionada
B24: 1º passo: Projeto (definir o empreendimento) | D24: TIROL
B26: 2º passo: Mês de análise (definir o mês de referência) | E26: 46266
B28: 3º passo: Orçamento da obra projetado (com INCC no a realizar) | J28: 30986800
B29: Tipo do orçamento | J29: Orçamento legal
B31: 4º passo: Previsto do mês (incluir o % do cronograma) | F31: 0.0303
B33: 5º passo: Executado do mês (incluir o % medido) | F33: 0.0345
B35: 6º passo: Previsto acumulado do mês | F35: 0.14
B37: 7º passo: Executado acumulado do mês | F37: 0.1095
B39: 8º passo: Crédito do orçamento (executado acumulado × orçamento) | F39: =F37*J28 -> 3393054.6
B41: 8º passo (cont.): Saldo de contrato (tabela) | F41: =E74 -> 0
B43: 9º passo: Adiantamento de serviços não medidos (tabela) | F43: =E88 -> 0
B45: 10º passo: Adiantamento de materiais não estocados (tabela) | F45: =J74 -> 0
B47: 11º passo: Estoque de materiais (almoxarifado) | F47: =J88 -> 160077.95
B49: 12º passo: Equipamentos comprados (valor de mercado) | F49: =E102 -> 76300
B51: 13º passo: Receitas de personalizações (tabela) | F51: =J102 -> 0
B53: 14º passo: Contas a pagar dos medidos (relatório a pagar) | F53: =E115 -> 184188.73
B55: 15º passo: Valor desembolsado pela obra (relatório conferido) | F55: 3342014.8
B56: Valor corrigido (sem os itens apontados irregularmente) | F56: =F55-J115 -> 3342014.8
B58: 16º passo: Dívida da obra a ser paga (outra obra da carteira) | F58: =E129 -> 0
B63: Saldo de contrato | G63: Adiantamento de materiais não estocados
B74: Total | E74: =SUM(E64:E73) -> 0 | G74: Total | J74: =SUM(J64:J73) -> 0
B77: Adiantamento de serviços não medidos | G77: Estoque de materiais
G78: Aço CA-50 para blocos e baldrame | J78: 60155.18
G79: Cimento e agregados | J79: 50861.87
G80: Madeira para formas | J80: 49060.9
B88: Total | E88: =SUM(E78:E87) -> 0 | G88: Total | J88: =SUM(J78:J87) -> 160077.95
B91: Equipamentos comprados | G91: Receitas de personalizações
B92: Betoneira 400 L | E92: 9800
B93: Guincho de coluna | E93: 38500
B94: Container escritório (2 un.) | E94: 28000
B102: Total | E102: =SUM(E92:E101) -> 76300 | G102: Total | J102: =SUM(J92:J101) -> 0
B105: Contas a pagar dos medidos | G105: Itens apontados irregularmente no relatório
B106: Medição de fundação (estacas hélice) · NF 15819 | E106: 69346.47
...
