Workbook

Sheet LEIA-ME
B2: Análise Crítica · CAJUEIRO
B3: Dados fictícios: construtora inventada de Natal/RN, portfólio Vizu Dados.
B4: Uma aba por mês (MMMAA). Os campos são lidos pelo rótulo da coluna B.
B5: Versão 01 da planilha: a dívida da obra (item 10) desconta do resultado.

Sheet SET25
B2: ANÁLISE DE DESEMPENHO ECONÔMICO DA OBRA
B3: Construtora fictícia de Natal/RN · portfólio Vizu Dados · dados inventados
B4: Versão 01 · revisão de 01/09/2025: a dívida da obra passa a descontar do resultado
B18: Célula editável
B19: Resultado (não editar)
B20: Tabela anexada
B21: % relacionada
B24: 1º passo: Projeto (definir o empreendimento) | D24: CAJUEIRO
B26: 2º passo: Mês de análise (definir o mês de referência) | E26: 45901
B28: 3º passo: Orçamento da obra projetado (com INCC no a realizar) | J28: 21400000
B29: Tipo do orçamento | J29: Orçamento final
B31: 4º passo: Previsto do mês (incluir o % do cronograma) | F31: 0.0368
B33: 5º passo: Executado do mês (incluir o % medido) | F33: 0.0368
B35: 6º passo: Previsto acumulado do mês | F35: 0.67
B37: 7º passo: Executado acumulado do mês | F37: 0.655
B39: 8º passo: Crédito do orçamento (executado acumulado × orçamento) | F39: =F37*J28 -> 14017000
B41: 8º passo (cont.): Saldo de contrato (tabela) | F41: =E74 -> 0
B43: 9º passo: Adiantamento de serviços não medidos (tabela) | F43: =E88 -> 0
B45: 10º passo: Adiantamento de materiais não estocados (tabela) | F45: =J74 -> 0
B47: 11º passo: Estoque de materiais (almoxarifado) | F47: =J88 -> 236925.2
B49: 12º passo: Equipamentos comprados (valor de mercado) | F49: =E102 -> 183300
B51: 13º passo: Receitas de personalizações (tabela) | F51: =J102 -> 382000
B53: 14º passo: Contas a pagar dos medidos (relatório a pagar) | F53: =E115 -> 154979.44
B55: 15º passo: Valor desembolsado pela obra (relatório conferido) | F55: 14314736
B56: Valor corrigido (sem os itens apontados irregularmente) | F56: =F55-J115 -> 14314736
B58: 16º passo: Dívida da obra a ser paga (outra obra da carteira) | F58: =E129 -> 0
B63: Saldo de contrato | G63: Adiantamento de materiais não estocados
B74: Total | E74: =SUM(E64:E73) -> 0 | G74: Total | J74: =SUM(J64:J73) -> 0
B77: Adiantamento de serviços não medidos | G77: Estoque de materiais
G78: Blocos cerâmicos | J78: 61781.96
G79: Argamassa industrializada | J79: 44220.37
G80: Material hidrossanitário | J80: 31720.14
G81: Material elétrico (fios e cabos) | J81: 41041.31
G82: Revestimento cerâmico (compra antecipada) | J82: 58161.42
B88: Total | E88: =SUM(E78:E87) -> 0 | G88: Total | J88: =SUM(J78:J87) -> 236925.2
B91: Equipamentos comprados | G91: Receitas de personalizações
B92: Betoneira 400 L | E92: 9800 | G92: Unid. 501 · troca de piso da sala (cliente I. Moura) | J92: 200553.59
B93: Guincho de coluna | E93: 38500 | G93: Unid. 1603 · bancada da cozinha em quartzo (cliente J. Viana) | J93: 181446.41
B94: Andaime fachadeiro (lote) | E94: 64000
B95: Plataforma elevatória | E95: 71000
...

Sheet OUT25
B2: ANÁLISE DE DESEMPENHO ECONÔMICO DA OBRA
B3: Construtora fictícia de Natal/RN · portfólio Vizu Dados · dados inventados
B4: Versão 01 · revisão de 01/09/2025: a dívida da obra passa a descontar do resultado
B18: Célula editável
B19: Resultado (não editar)
B20: Tabela anexada
B21: % relacionada
B24: 1º passo: Projeto (definir o empreendimento) | D24: CAJUEIRO
B26: 2º passo: Mês de análise (definir o mês de referência) | E26: 45931
B28: 3º passo: Orçamento da obra projetado (com INCC no a realizar) | J28: 21489880
B29: Tipo do orçamento | J29: Orçamento final
B31: 4º passo: Previsto do mês (incluir o % do cronograma) | F31: 0.0359
B33: 5º passo: Executado do mês (incluir o % medido) | F33: 0.0359
B35: 6º passo: Previsto acumulado do mês | F35: 0.7059
B37: 7º passo: Executado acumulado do mês | F37: 0.6909
B39: 8º passo: Crédito do orçamento (executado acumulado × orçamento) | F39: =F37*J28 -> 14847358
B41: 8º passo (cont.): Saldo de contrato (tabela) | F41: =E74 -> 0
B43: 9º passo: Adiantamento de serviços não medidos (tabela) | F43: =E88 -> 0
B45: 10º passo: Adiantamento de materiais não estocados (tabela) | F45: =J74 -> 0
B47: 11º passo: Estoque de materiais (almoxarifado) | F47: =J88 -> 240572.92
B49: 12º passo: Equipamentos comprados (valor de mercado) | F49: =E102 -> 183300
B51: 13º passo: Receitas de personalizações (tabela) | F51: =J102 -> 399500
B53: 14º passo: Contas a pagar dos medidos (relatório a pagar) | F53: =E115 -> 149338.74
B55: 15º passo: Valor desembolsado pela obra (relatório conferido) | F55: 15149965
B56: Valor corrigido (sem os itens apontados irregularmente) | F56: =F55-J115 -> 15149965
B58: 16º passo: Dívida da obra a ser paga (outra obra da carteira) | F58: =E129 -> 0
B63: Saldo de contrato | G63: Adiantamento de materiais não estocados
B74: Total | E74: =SUM(E64:E73) -> 0 | G74: Total | J74: =SUM(J64:J73) -> 0
B77: Adiantamento de serviços não medidos | G77: Estoque de materiais
G78: Blocos cerâmicos | J78: 40523.37
G79: Argamassa industrializada | J79: 44741.74
G80: Material hidrossanitário | J80: 55905.26
G81: Material elétrico (fios e cabos) | J81: 50588.27
G82: Revestimento cerâmico (compra antecipada) | J82: 48814.28
B88: Total | E88: =SUM(E78:E87) -> 0 | G88: Total | J88: =SUM(J78:J87) -> 240572.92
B91: Equipamentos comprados | G91: Receitas de personalizações
B92: Betoneira 400 L | E92: 9800 | G92: Unid. 501 · troca de piso da sala (cliente I. Moura) | J92: 209741.25
B93: Guincho de coluna | E93: 38500 | G93: Unid. 1603 · bancada da cozinha em quartzo (cliente J. Viana) | J93: 189758.75
B94: Andaime fachadeiro (lote) | E94: 64000
B95: Plataforma elevatória | E95: 71000
...

Sheet NOV25
B2: ANÁLISE DE DESEMPENHO ECONÔMICO DA OBRA
B3: Construtora fictícia de Natal/RN · portfólio Vizu Dados · dados inventados
B4: Versão 01 · revisão de 01/09/2025: a dívida da obra passa a descontar do resultado
B18: Célula editável
B19: Resultado (não editar)
B20: Tabela anexada
B21: % relacionada
B24: 1º passo: Projeto (definir o empreendimento) | D24: CAJUEIRO
B26: 2º passo: Mês de análise (definir o mês de referência) | E26: 45962
B28: 3º passo: Orçamento da obra projetado (com INCC no a realizar) | J28: 21579760
B29: Tipo do orçamento | J29: Orçamento final
B31: 4º passo: Previsto do mês (incluir o % do cronograma) | F31: 0.0348
B33: 5º passo: Executado do mês (incluir o % medido) | F33: 0.0348
B35: 6º passo: Previsto acumulado do mês | F35: 0.7407
B37: 7º passo: Executado acumulado do mês | F37: 0.7257
B39: 8º passo: Crédito do orçamento (executado acumulado × orçamento) | F39: =F37*J28 -> 15660432
B41: 8º passo (cont.): Saldo de contrato (tabela) | F41: =E74 -> 0
B43: 9º passo: Adiantamento de serviços não medidos (tabela) | F43: =E88 -> 0
B45: 10º passo: Adiantamento de materiais não estocados (tabela) | F45: =J74 -> 0
B47: 11º passo: Estoque de materiais (almoxarifado) | F47: =J88 -> 284802.3
B49: 12º passo: Equipamentos comprados (valor de mercado) | F49: =E102 -> 183300
B51: 13º passo: Receitas de personalizações (tabela) | F51: =J102 -> 417000
B53: 14º passo: Contas a pagar dos medidos (relatório a pagar) | F53: =E115 -> 125336.38
B55: 15º passo: Valor desembolsado pela obra (relatório conferido) | F55: 16025757
B56: Valor corrigido (sem os itens apontados irregularmente) | F56: =F55-J115 -> 16025757
B58: 16º passo: Dívida da obra a ser paga (outra obra da carteira) | F58: =E129 -> 0
B63: Saldo de contrato | G63: Adiantamento de materiais não estocados
B74: Total | E74: =SUM(E64:E73) -> 0 | G74: Total | J74: =SUM(J64:J73) -> 0
B77: Adiantamento de serviços não medidos | G77: Estoque de materiais
G78: Blocos cerâmicos | J78: 40643.05
G79: Argamassa industrializada | J79: 74953.6
G80: Material hidrossanitário | J80: 61944.46
G81: Material elétrico (fios e cabos) | J81: 52782.66
G82: Revestimento cerâmico (compra antecipada) | J82: 54478.53
B88: Total | E88: =SUM(E78:E87) -> 0 | G88: Total | J88: =SUM(J78:J87) -> 284802.3
B91: Equipamentos comprados | G91: Receitas de personalizações
B92: Betoneira 400 L | E92: 9800 | G92: Unid. 501 · troca de piso da sala (cliente I. Moura) | J92: 142707.75
B93: Guincho de coluna | E93: 38500 | G93: Unid. 1603 · bancada da cozinha em quartzo (cliente J. Viana) | J93: 129111.67
B94: Andaime fachadeiro (lote) | E94: 64000 | G94: Unid. 401 · planta com home office (cliente K. Saraiva) | J94: 145180.58
B95: Plataforma elevatória | E95: 71000
...

Sheet DEZ25
B2: ANÁLISE DE DESEMPENHO ECONÔMICO DA OBRA
B3: Construtora fictícia de Natal/RN · portfólio Vizu Dados · dados inventados
B4: Versão 01 · revisão de 01/09/2025: a dívida da obra passa a descontar do resultado
B18: Célula editável
B19: Resultado (não editar)
B20: Tabela anexada
B21: % relacionada
B24: 1º passo: Projeto (definir o empreendimento) | D24: CAJUEIRO
B26: 2º passo: Mês de análise (definir o mês de referência) | E26: 45992
B28: 3º passo: Orçamento da obra projetado (com INCC no a realizar) | J28: 21669640
B29: Tipo do orçamento | J29: Orçamento final
B31: 4º passo: Previsto do mês (incluir o % do cronograma) | F31: 0.0335
B33: 5º passo: Executado do mês (incluir o % medido) | F33: 0.0332
B35: 6º passo: Previsto acumulado do mês | F35: 0.7742
B37: 7º passo: Executado acumulado do mês | F37: 0.7589
B39: 8º passo: Crédito do orçamento (executado acumulado × orçamento) | F39: =F37*J28 -> 16445090
B41: 8º passo (cont.): Saldo de contrato (tabela) | F41: =E74 -> 0
B43: 9º passo: Adiantamento de serviços não medidos (tabela) | F43: =E88 -> 0
B45: 10º passo: Adiantamento de materiais não estocados (tabela) | F45: =J74 -> 0
B47: 11º passo: Estoque de materiais (almoxarifado) | F47: =J88 -> 260170.11
B49: 12º passo: Equipamentos comprados (valor de mercado) | F49: =E102 -> 183300
B51: 13º passo: Receitas de personalizações (tabela) | F51: =J102 -> 434500
B53: 14º passo: Contas a pagar dos medidos (relatório a pagar) | F53: =E115 -> 151887.8
B55: 15º passo: Valor desembolsado pela obra (relatório conferido) | F55: 16752826
B56: Valor corrigido (sem os itens apontados irregularmente) | F56: =F55-J115 -> 16752826
B58: 16º passo: Dívida da obra a ser paga (outra obra da carteira) | F58: =E129 -> 0
B63: Saldo de contrato | G63: Adiantamento de materiais não estocados
B74: Total | E74: =SUM(E64:E73) -> 0 | G74: Total | J74: =SUM(J64:J73) -> 0
B77: Adiantamento de serviços não medidos | G77: Estoque de materiais
G78: Blocos cerâmicos | J78: 39373.26
G79: Argamassa industrializada | J79: 48983.29
G80: Material hidrossanitário | J80: 65189.66
G81: Material elétrico (fios e cabos) | J81: 62713.38
G82: Revestimento cerâmico (compra antecipada) | J82: 43910.52
B88: Total | E88: =SUM(E78:E87) -> 0 | G88: Total | J88: =SUM(J78:J87) -> 260170.11
B91: Equipamentos comprados | G91: Receitas de personalizações
B92: Betoneira 400 L | E92: 9800 | G92: Unid. 501 · troca de piso da sala (cliente I. Moura) | J92: 148696.69
B93: Guincho de coluna | E93: 38500 | G93: Unid. 1603 · bancada da cozinha em quartzo (cliente J. Viana) | J93: 134530.03
B94: Andaime fachadeiro (lote) | E94: 64000 | G94: Unid. 401 · planta com home office (cliente K. Saraiva) | J94: 151273.28
B95: Plataforma elevatória | E95: 71000
...

Sheet JAN26
B2: ANÁLISE DE DESEMPENHO ECONÔMICO DA OBRA
B3: Construtora fictícia de Natal/RN · portfólio Vizu Dados · dados inventados
B4: Versão 01 · revisão de 01/09/2025: a dívida da obra passa a descontar do resultado
B18: Célula editável
B19: Resultado (não editar)
B20: Tabela anexada
B21: % relacionada
B24: 1º passo: Projeto (definir o empreendimento) | D24: CAJUEIRO
B26: 2º passo: Mês de análise (definir o mês de referência) | E26: 46023
B28: 3º passo: Orçamento da obra projetado (com INCC no a realizar) | J28: 21759520
B29: Tipo do orçamento | J29: Orçamento final
B31: 4º passo: Previsto do mês (incluir o % do cronograma) | F31: 0.032
B33: 5º passo: Executado do mês (incluir o % medido) | F33: 0.0317
B35: 6º passo: Previsto acumulado do mês | F35: 0.8062
B37: 7º passo: Executado acumulado do mês | F37: 0.7906
B39: 8º passo: Crédito do orçamento (executado acumulado × orçamento) | F39: =F37*J28 -> 17203077
B41: 8º passo (cont.): Saldo de contrato (tabela) | F41: =E74 -> 0
B43: 9º passo: Adiantamento de serviços não medidos (tabela) | F43: =E88 -> 0
B45: 10º passo: Adiantamento de materiais não estocados (tabela) | F45: =J74 -> 0
B47: 11º passo: Estoque de materiais (almoxarifado) | F47: =J88 -> 302186.67
B49: 12º passo: Equipamentos comprados (valor de mercado) | F49: =E102 -> 183300
B51: 13º passo: Receitas de personalizações (tabela) | F51: =J102 -> 452000
B53: 14º passo: Contas a pagar dos medidos (relatório a pagar) | F53: =E115 -> 153622.69
B55: 15º passo: Valor desembolsado pela obra (relatório conferido) | F55: 17543844
B56: Valor corrigido (sem os itens apontados irregularmente) | F56: =F55-J115 -> 17543844
B58: 16º passo: Dívida da obra a ser paga (outra obra da carteira) | F58: =E129 -> 0
B63: Saldo de contrato | G63: Adiantamento de materiais não estocados
B74: Total | E74: =SUM(E64:E73) -> 0 | G74: Total | J74: =SUM(J64:J73) -> 0
B77: Adiantamento de serviços não medidos | G77: Estoque de materiais
G78: Blocos cerâmicos | J78: 60504.84
G79: Argamassa industrializada | J79: 51972.91
G80: Material hidrossanitário | J80: 76437.02
G81: Material elétrico (fios e cabos) | J81: 47176.25
G82: Revestimento cerâmico (compra antecipada) | J82: 66095.65
B88: Total | E88: =SUM(E78:E87) -> 0 | G88: Total | J88: =SUM(J78:J87) -> 302186.67
B91: Equipamentos comprados | G91: Receitas de personalizações
B92: Betoneira 400 L | E92: 9800 | G92: Unid. 501 · troca de piso da sala (cliente I. Moura) | J92: 120733.03
B93: Guincho de coluna | E93: 38500 | G93: Unid. 1603 · bancada da cozinha em quartzo (cliente J. Viana) | J93: 109230.54
B94: Andaime fachadeiro (lote) | E94: 64000 | G94: Unid. 401 · planta com home office (cliente K. Saraiva) | J94: 122825.08
B95: Plataforma elevatória | E95: 71000 | G95: Unid. 201 · ponto extra de ar-condicionado (cliente L. Fernandes) | J95: 99211.35
...

Sheet FEV26
B2: ANÁLISE DE DESEMPENHO ECONÔMICO DA OBRA
B3: Construtora fictícia de Natal/RN · portfólio Vizu Dados · dados inventados
B4: Versão 01 · revisão de 01/09/2025: a dívida da obra passa a descontar do resultado
B18: Célula editável
B19: Resultado (não editar)
B20: Tabela anexada
B21: % relacionada
B24: 1º passo: Projeto (definir o empreendimento) | D24: CAJUEIRO
B26: 2º passo: Mês de análise (definir o mês de referência) | E26: 46054
B28: 3º passo: Orçamento da obra projetado (com INCC no a realizar) | J28: 21849400
B29: Tipo do orçamento | J29: Orçamento final
B31: 4º passo: Previsto do mês (incluir o % do cronograma) | F31: 0.0303
B33: 5º passo: Executado do mês (incluir o % medido) | F33: 0.0291
B35: 6º passo: Previsto acumulado do mês | F35: 0.8365
B37: 7º passo: Executado acumulado do mês | F37: 0.8197
B39: 8º passo: Crédito do orçamento (executado acumulado × orçamento) | F39: =F37*J28 -> 17909953
B41: 8º passo (cont.): Saldo de contrato (tabela) | F41: =E74 -> 0
B43: 9º passo: Adiantamento de serviços não medidos (tabela) | F43: =E88 -> 0
B45: 10º passo: Adiantamento de materiais não estocados (tabela) | F45: =J74 -> 0
B47: 11º passo: Estoque de materiais (almoxarifado) | F47: =J88 -> 180829.82
B49: 12º passo: Equipamentos comprados (valor de mercado) | F49: =E102 -> 183300
B51: 13º passo: Receitas de personalizações (tabela) | F51: =J102 -> 469500
B53: 14º passo: Contas a pagar dos medidos (relatório a pagar) | F53: =E115 -> 135084.84
B55: 15º passo: Valor desembolsado pela obra (relatório conferido) | F55: 18140260
B56: Valor corrigido (sem os itens apontados irregularmente) | F56: =F55-J115 -> 18140260
B58: 16º passo: Dívida da obra a ser paga (outra obra da carteira) | F58: =E129 -> 0
B63: Saldo de contrato | G63: Adiantamento de materiais não estocados
B74: Total | E74: =SUM(E64:E73) -> 0 | G74: Total | J74: =SUM(J64:J73) -> 0
B77: Adiantamento de serviços não medidos | G77: Estoque de materiais
G78: Revestimento cerâmico interno | J78: 34606.4
G79: Porcelanato das áreas comuns | J79: 20762.94
G80: Louças e metais | J80: 18864.8
G81: Material elétrico (fios e cabos) | J81: 35425.8
G82: Tinta acrílica | J82: 32417.33
G83: Material para impermeabilização | J83: 38752.55
B88: Total | E88: =SUM(E78:E87) -> 0 | G88: Total | J88: =SUM(J78:J87) -> 180829.82
B91: Equipamentos comprados | G91: Receitas de personalizações
B92: Betoneira 400 L | E92: 9800 | G92: Unid. 501 · troca de piso da sala (cliente I. Moura) | J92: 125407.43
B93: Guincho de coluna | E93: 38500 | G93: Unid. 1603 · bancada da cozinha em quartzo (cliente J. Viana) | J93: 113459.59
B94: Andaime fachadeiro (lote) | E94: 64000 | G94: Unid. 401 · planta com home office (cliente K. Saraiva) | J94: 127580.48
...

Sheet MAR26
B2: ANÁLISE DE DESEMPENHO ECONÔMICO DA OBRA
B3: Construtora fictícia de Natal/RN · portfólio Vizu Dados · dados inventados
B4: Versão 01 · revisão de 01/09/2025: a dívida da obra passa a descontar do resultado
B18: Célula editável
B19: Resultado (não editar)
B20: Tabela anexada
B21: % relacionada
B24: 1º passo: Projeto (definir o empreendimento) | D24: CAJUEIRO
B26: 2º passo: Mês de análise (definir o mês de referência) | E26: 46082
B28: 3º passo: Orçamento da obra projetado (com INCC no a realizar) | J28: 21939280
B29: Tipo do orçamento | J29: Orçamento final
B31: 4º passo: Previsto do mês (incluir o % do cronograma) | F31: 0.0283
B33: 5º passo: Executado do mês (incluir o % medido) | F33: 0.028
B35: 6º passo: Previsto acumulado do mês | F35: 0.8648
B37: 7º passo: Executado acumulado do mês | F37: 0.8477
B39: 8º passo: Crédito do orçamento (executado acumulado × orçamento) | F39: =F37*J28 -> 18597928
B41: 8º passo (cont.): Saldo de contrato (tabela) | F41: =E74 -> 0
B43: 9º passo: Adiantamento de serviços não medidos (tabela) | F43: =E88 -> 0
B45: 10º passo: Adiantamento de materiais não estocados (tabela) | F45: =J74 -> 0
B47: 11º passo: Estoque de materiais (almoxarifado) | F47: =J88 -> 181531.32
B49: 12º passo: Equipamentos comprados (valor de mercado) | F49: =E102 -> 183300
B51: 13º passo: Receitas de personalizações (tabela) | F51: =J102 -> 487000
B53: 14º passo: Contas a pagar dos medidos (relatório a pagar) | F53: =E115 -> 150667.38
B55: 15º passo: Valor desembolsado pela obra (relatório conferido) | F55: 18804912
B56: Valor corrigido (sem os itens apontados irregularmente) | F56: =F55-J115 -> 18804912
B58: 16º passo: Dívida da obra a ser paga (outra obra da carteira) | F58: =E129 -> 0
B63: Saldo de contrato | G63: Adiantamento de materiais não estocados
B74: Total | E74: =SUM(E64:E73) -> 0 | G74: Total | J74: =SUM(J64:J73) -> 0
B77: Adiantamento de serviços não medidos | G77: Estoque de materiais
G78: Revestimento cerâmico interno | J78: 28765.73
G79: Porcelanato das áreas comuns | J79: 30209.69
G80: Louças e metais | J80: 28738.11
G81: Material elétrico (fios e cabos) | J81: 30441.33
G82: Tinta acrílica | J82: 34017.84
G83: Material para impermeabilização | J83: 29358.62
B88: Total | E88: =SUM(E78:E87) -> 0 | G88: Total | J88: =SUM(J78:J87) -> 181531.32
B91: Equipamentos comprados | G91: Receitas de personalizações
B92: Betoneira 400 L | E92: 9800 | G92: Unid. 501 · troca de piso da sala (cliente I. Moura) | J92: 109912.13
B93: Guincho de coluna | E93: 38500 | G93: Unid. 1603 · bancada da cozinha em quartzo (cliente J. Viana) | J93: 99440.57
B94: Andaime fachadeiro (lote) | E94: 64000 | G94: Unid. 401 · planta com home office (cliente K. Saraiva) | J94: 111816.68
...

Sheet ABR26
B2: ANÁLISE DE DESEMPENHO ECONÔMICO DA OBRA
B3: Construtora fictícia de Natal/RN · portfólio Vizu Dados · dados inventados
B4: Versão 01 · revisão de 01/09/2025: a dívida da obra passa a descontar do resultado
B18: Célula editável
B19: Resultado (não editar)
B20: Tabela anexada
B21: % relacionada
B24: 1º passo: Projeto (definir o empreendimento) | D24: CAJUEIRO
B26: 2º passo: Mês de análise (definir o mês de referência) | E26: 46113
B28: 3º passo: Orçamento da obra projetado (com INCC no a realizar) | J28: 22029160
B29: Tipo do orçamento | J29: Orçamento final
B31: 4º passo: Previsto do mês (incluir o % do cronograma) | F31: 0.0262
B33: 5º passo: Executado do mês (incluir o % medido) | F33: 0.0252
B35: 6º passo: Previsto acumulado do mês | F35: 0.891
B37: 7º passo: Executado acumulado do mês | F37: 0.8729
B39: 8º passo: Crédito do orçamento (executado acumulado × orçamento) | F39: =F37*J28 -> 19229254
B41: 8º passo (cont.): Saldo de contrato (tabela) | F41: =E74 -> 0
B43: 9º passo: Adiantamento de serviços não medidos (tabela) | F43: =E88 -> 0
B45: 10º passo: Adiantamento de materiais não estocados (tabela) | F45: =J74 -> 0
B47: 11º passo: Estoque de materiais (almoxarifado) | F47: =J88 -> 216114.16
B49: 12º passo: Equipamentos comprados (valor de mercado) | F49: =E102 -> 183300
B51: 13º passo: Receitas de personalizações (tabela) | F51: =J102 -> 504500
B53: 14º passo: Contas a pagar dos medidos (relatório a pagar) | F53: =E115 -> 112131.97
B55: 15º passo: Valor desembolsado pela obra (relatório conferido) | F55: 19522502
B56: Valor corrigido (sem os itens apontados irregularmente) | F56: =F55-J115 -> 19522502
B58: 16º passo: Dívida da obra a ser paga (outra obra da carteira) | F58: =E129 -> 0
B63: Saldo de contrato | G63: Adiantamento de materiais não estocados
B74: Total | E74: =SUM(E64:E73) -> 0 | G74: Total | J74: =SUM(J64:J73) -> 0
B77: Adiantamento de serviços não medidos | G77: Estoque de materiais
G78: Revestimento cerâmico interno | J78: 28725.62
G79: Porcelanato das áreas comuns | J79: 46064.94
G80: Louças e metais | J80: 33191.72
G81: Material elétrico (fios e cabos) | J81: 24974.82
G82: Tinta acrílica | J82: 42241.78
G83: Material para impermeabilização | J83: 40915.28
B88: Total | E88: =SUM(E78:E87) -> 0 | G88: Total | J88: =SUM(J78:J87) -> 216114.16
B91: Equipamentos comprados | G91: Receitas de personalizações
B92: Betoneira 400 L | E92: 9800 | G92: Unid. 501 · troca de piso da sala (cliente I. Moura) | J92: 113861.75
B93: Guincho de coluna | E93: 38500 | G93: Unid. 1603 · bancada da cozinha em quartzo (cliente J. Viana) | J93: 103013.89
B94: Andaime fachadeiro (lote) | E94: 64000 | G94: Unid. 401 · planta com home office (cliente K. Saraiva) | J94: 115834.73
...

Sheet MAI26
B2: ANÁLISE DE DESEMPENHO ECONÔMICO DA OBRA
B3: Construtora fictícia de Natal/RN · portfólio Vizu Dados · dados inventados
B4: Versão 01 · revisão de 01/09/2025: a dívida da obra passa a descontar do resultado
B18: Célula editável
B19: Resultado (não editar)
B20: Tabela anexada
B21: % relacionada
B24: 1º passo: Projeto (definir o empreendimento) | D24: CAJUEIRO
B26: 2º passo: Mês de análise (definir o mês de referência) | E26: 46143
B28: 3º passo: Orçamento da obra projetado (com INCC no a realizar) | J28: 22119040
B29: Tipo do orçamento | J29: Orçamento final
B31: 4º passo: Previsto do mês (incluir o % do cronograma) | F31: 0.0239
B33: 5º passo: Executado do mês (incluir o % medido) | F33: 0.0237
B35: 6º passo: Previsto acumulado do mês | F35: 0.9149
B37: 7º passo: Executado acumulado do mês | F37: 0.8966
B39: 8º passo: Crédito do orçamento (executado acumulado × orçamento) | F39: =F37*J28 -> 19831931
B41: 8º passo (cont.): Saldo de contrato (tabela) | F41: =E74 -> 0
B43: 9º passo: Adiantamento de serviços não medidos (tabela) | F43: =E88 -> 0
B45: 10º passo: Adiantamento de materiais não estocados (tabela) | F45: =J74 -> 0
B47: 11º passo: Estoque de materiais (almoxarifado) | F47: =J88 -> 217652.63
B49: 12º passo: Equipamentos comprados (valor de mercado) | F49: =E102 -> 183300
B51: 13º passo: Receitas de personalizações (tabela) | F51: =J102 -> 522000
B53: 14º passo: Contas a pagar dos medidos (relatório a pagar) | F53: =E115 -> 126255.97
B55: 15º passo: Valor desembolsado pela obra (relatório conferido) | F55: 20126612
B56: Valor corrigido (sem os itens apontados irregularmente) | F56: =F55-J115 -> 20126612
B58: 16º passo: Dívida da obra a ser paga (outra obra da carteira) | F58: =E129 -> 0
B63: Saldo de contrato | G63: Adiantamento de materiais não estocados
B74: Total | E74: =SUM(E64:E73) -> 0 | G74: Total | J74: =SUM(J64:J73) -> 0
B77: Adiantamento de serviços não medidos | G77: Estoque de materiais
G78: Revestimento cerâmico interno | J78: 24734.13
G79: Porcelanato das áreas comuns | J79: 32918.92
G80: Louças e metais | J80: 47111.9
G81: Material elétrico (fios e cabos) | J81: 43920.09
G82: Tinta acrílica | J82: 27087.34
G83: Material para impermeabilização | J83: 41880.25
B88: Total | E88: =SUM(E78:E87) -> 0 | G88: Total | J88: =SUM(J78:J87) -> 217652.63
B91: Equipamentos comprados | G91: Receitas de personalizações
B92: Betoneira 400 L | E92: 9800 | G92: Unid. 501 · troca de piso da sala (cliente I. Moura) | J92: 97831.71
B93: Guincho de coluna | E93: 38500 | G93: Unid. 1603 · bancada da cozinha em quartzo (cliente J. Viana) | J93: 88511.07
B94: Andaime fachadeiro (lote) | E94: 64000 | G94: Unid. 401 · planta com home office (cliente K. Saraiva) | J94: 99526.93
...

Sheet JUN26
B2: ANÁLISE DE DESEMPENHO ECONÔMICO DA OBRA
B3: Construtora fictícia de Natal/RN · portfólio Vizu Dados · dados inventados
B4: Versão 01 · revisão de 01/09/2025: a dívida da obra passa a descontar do resultado
B18: Célula editável
B19: Resultado (não editar)
B20: Tabela anexada
B21: % relacionada
B24: 1º passo: Projeto (definir o empreendimento) | D24: CAJUEIRO
B26: 2º passo: Mês de análise (definir o mês de referência) | E26: 46174
B28: 3º passo: Orçamento da obra projetado (com INCC no a realizar) | J28: 22208920
B29: Tipo do orçamento | J29: Orçamento final
B31: 4º passo: Previsto do mês (incluir o % do cronograma) | F31: 0.0214
B33: 5º passo: Executado do mês (incluir o % medido) | F33: 0.0219
B35: 6º passo: Previsto acumulado do mês | F35: 0.9363
B37: 7º passo: Executado acumulado do mês | F37: 0.9185
B39: 8º passo: Crédito do orçamento (executado acumulado × orçamento) | F39: =F37*J28 -> 20398893
B41: 8º passo (cont.): Saldo de contrato (tabela) | F41: =E74 -> 0
B43: 9º passo: Adiantamento de serviços não medidos (tabela) | F43: =E88 -> 0
B45: 10º passo: Adiantamento de materiais não estocados (tabela) | F45: =J74 -> 0
B47: 11º passo: Estoque de materiais (almoxarifado) | F47: =J88 -> 190387.92
B49: 12º passo: Equipamentos comprados (valor de mercado) | F49: =E102 -> 183300
B51: 13º passo: Receitas de personalizações (tabela) | F51: =J102 -> 539500
B53: 14º passo: Contas a pagar dos medidos (relatório a pagar) | F53: =E115 -> 91273.27
B55: 15º passo: Valor desembolsado pela obra (relatório conferido) | F55: 20716265
B56: Valor corrigido (sem os itens apontados irregularmente) | F56: =F55-J115 -> 20716265
B58: 16º passo: Dívida da obra a ser paga (outra obra da carteira) | F58: =E129 -> 0
B63: Saldo de contrato | G63: Adiantamento de materiais não estocados
B74: Total | E74: =SUM(E64:E73) -> 0 | G74: Total | J74: =SUM(J64:J73) -> 0
B77: Adiantamento de serviços não medidos | G77: Estoque de materiais
G78: Revestimento cerâmico interno | J78: 33104.49
G79: Porcelanato das áreas comuns | J79: 36778.08
G80: Louças e metais | J80: 21266.64
G81: Material elétrico (fios e cabos) | J81: 26071.12
G82: Tinta acrílica | J82: 35901.11
G83: Material para impermeabilização | J83: 37266.48
B88: Total | E88: =SUM(E78:E87) -> 0 | G88: Total | J88: =SUM(J78:J87) -> 190387.92
B91: Equipamentos comprados | G91: Receitas de personalizações
B92: Betoneira 400 L | E92: 9800 | G92: Unid. 501 · troca de piso da sala (cliente I. Moura) | J92: 101111.51
B93: Guincho de coluna | E93: 38500 | G93: Unid. 1603 · bancada da cozinha em quartzo (cliente J. Viana) | J93: 91478.4
B94: Andaime fachadeiro (lote) | E94: 64000 | G94: Unid. 401 · planta com home office (cliente K. Saraiva) | J94: 102863.56
...

Sheet JUL26
B2: ANÁLISE DE DESEMPENHO ECONÔMICO DA OBRA
B3: Construtora fictícia de Natal/RN · portfólio Vizu Dados · dados inventados
B4: Versão 01 · revisão de 01/09/2025: a dívida da obra passa a descontar do resultado
B18: Célula editável
B19: Resultado (não editar)
B20: Tabela anexada
B21: % relacionada
B24: 1º passo: Projeto (definir o empreendimento) | D24: CAJUEIRO
B26: 2º passo: Mês de análise (definir o mês de referência) | E26: 46204
B28: 3º passo: Orçamento da obra projetado (com INCC no a realizar) | J28: 22298800
B29: Tipo do orçamento | J29: Orçamento final
B31: 4º passo: Previsto do mês (incluir o % do cronograma) | F31: 0.0186
B33: 5º passo: Executado do mês (incluir o % medido) | F33: 0.0197
B35: 6º passo: Previsto acumulado do mês | F35: 0.9549
B37: 7º passo: Executado acumulado do mês | F37: 0.9382
B39: 8º passo: Crédito do orçamento (executado acumulado × orçamento) | F39: =F37*J28 -> 20920734
B41: 8º passo (cont.): Saldo de contrato (tabela) | F41: =E74 -> 0
B43: 9º passo: Adiantamento de serviços não medidos (tabela) | F43: =E88 -> 0
B45: 10º passo: Adiantamento de materiais não estocados (tabela) | F45: =J74 -> 0
B47: 11º passo: Estoque de materiais (almoxarifado) | F47: =J88 -> 220847.31
B49: 12º passo: Equipamentos comprados (valor de mercado) | F49: =E102 -> 183300
B51: 13º passo: Receitas de personalizações (tabela) | F51: =J102 -> 557000
B53: 14º passo: Contas a pagar dos medidos (relatório a pagar) | F53: =E115 -> 85706.45
B55: 15º passo: Valor desembolsado pela obra (relatório conferido) | F55: 21290173
B56: Valor corrigido (sem os itens apontados irregularmente) | F56: =F55-J115 -> 21290173
B58: 16º passo: Dívida da obra a ser paga (outra obra da carteira) | F58: =E129 -> 0
B63: Saldo de contrato | G63: Adiantamento de materiais não estocados
B74: Total | E74: =SUM(E64:E73) -> 0 | G74: Total | J74: =SUM(J64:J73) -> 0
B77: Adiantamento de serviços não medidos | G77: Estoque de materiais
G78: Revestimento cerâmico interno | J78: 43706.24
G79: Porcelanato das áreas comuns | J79: 25781.31
G80: Louças e metais | J80: 34372.29
G81: Material elétrico (fios e cabos) | J81: 33673.58
G82: Tinta acrílica | J82: 54260.27
G83: Material para impermeabilização | J83: 29053.62
B88: Total | E88: =SUM(E78:E87) -> 0 | G88: Total | J88: =SUM(J78:J87) -> 220847.31
B91: Equipamentos comprados | G91: Receitas de personalizações
B92: Betoneira 400 L | E92: 9800 | G92: Unid. 501 · troca de piso da sala (cliente I. Moura) | J92: 85730.76
B93: Guincho de coluna | E93: 38500 | G93: Unid. 1603 · bancada da cozinha em quartzo (cliente J. Viana) | J93: 77563.01
B94: Andaime fachadeiro (lote) | E94: 64000 | G94: Unid. 401 · planta com home office (cliente K. Saraiva) | J94: 87216.29
...

Sheet AGO26
B2: ANÁLISE DE DESEMPENHO ECONÔMICO DA OBRA
B3: Construtora fictícia de Natal/RN · portfólio Vizu Dados · dados inventados
B4: Versão 01 · revisão de 01/09/2025: a dívida da obra passa a descontar do resultado
B18: Célula editável
B19: Resultado (não editar)
B20: Tabela anexada
B21: % relacionada
B24: 1º passo: Projeto (definir o empreendimento) | D24: CAJUEIRO
B26: 2º passo: Mês de análise (definir o mês de referência) | E26: 46235
B28: 3º passo: Orçamento da obra projetado (com INCC no a realizar) | J28: 22388680
B29: Tipo do orçamento | J29: Orçamento final
B31: 4º passo: Previsto do mês (incluir o % do cronograma) | F31: 0.0157
B33: 5º passo: Executado do mês (incluir o % medido) | F33: 0.0202
B35: 6º passo: Previsto acumulado do mês | F35: 0.9706
B37: 7º passo: Executado acumulado do mês | F37: 0.9584
B39: 8º passo: Crédito do orçamento (executado acumulado × orçamento) | F39: =F37*J28 -> 21457311
B41: 8º passo (cont.): Saldo de contrato (tabela) | F41: =E74 -> 0
B43: 9º passo: Adiantamento de serviços não medidos (tabela) | F43: =E88 -> 0
B45: 10º passo: Adiantamento de materiais não estocados (tabela) | F45: =J74 -> 0
B47: 11º passo: Estoque de materiais (almoxarifado) | F47: =J88 -> 237201.62
B49: 12º passo: Equipamentos comprados (valor de mercado) | F49: =E102 -> 183300
B51: 13º passo: Receitas de personalizações (tabela) | F51: =J102 -> 574500
B53: 14º passo: Contas a pagar dos medidos (relatório a pagar) | F53: =E115 -> 72903.09
B55: 15º passo: Valor desembolsado pela obra (relatório conferido) | F55: 21872066
B56: Valor corrigido (sem os itens apontados irregularmente) | F56: =F55-J115 -> 21872066
B58: 16º passo: Dívida da obra a ser paga (outra obra da carteira) | F58: =E129 -> 0
B63: Saldo de contrato | G63: Adiantamento de materiais não estocados
B74: Total | E74: =SUM(E64:E73) -> 0 | G74: Total | J74: =SUM(J64:J73) -> 0
B77: Adiantamento de serviços não medidos | G77: Estoque de materiais
G78: Revestimento cerâmico interno | J78: 32084.76
G79: Porcelanato das áreas comuns | J79: 46198.98
G80: Louças e metais | J80: 50591.58
G81: Material elétrico (fios e cabos) | J81: 29720.6
G82: Tinta acrílica | J82: 42141.89
G83: Material para impermeabilização | J83: 36463.81
B88: Total | E88: =SUM(E78:E87) -> 0 | G88: Total | J88: =SUM(J78:J87) -> 237201.62
B91: Equipamentos comprados | G91: Receitas de personalizações
B92: Betoneira 400 L | E92: 9800 | G92: Unid. 501 · troca de piso da sala (cliente I. Moura) | J92: 88424.28
B93: Guincho de coluna | E93: 38500 | G93: Unid. 1603 · bancada da cozinha em quartzo (cliente J. Viana) | J93: 79999.9
B94: Andaime fachadeiro (lote) | E94: 64000 | G94: Unid. 401 · planta com home office (cliente K. Saraiva) | J94: 89956.48
...

Sheet SET26
B2: ANÁLISE DE DESEMPENHO ECONÔMICO DA OBRA
B3: Construtora fictícia de Natal/RN · portfólio Vizu Dados · dados inventados
B4: Versão 01 · revisão de 01/09/2025: a dívida da obra passa a descontar do resultado
B18: Célula editável
B19: Resultado (não editar)
B20: Tabela anexada
B21: % relacionada
B24: 1º passo: Projeto (definir o empreendimento) | D24: CAJUEIRO
B26: 2º passo: Mês de análise (definir o mês de referência) | E26: 46266
B28: 3º passo: Orçamento da obra projetado (com INCC no a realizar) | J28: 22478560
B29: Tipo do orçamento | J29: Orçamento final
B31: 4º passo: Previsto do mês (incluir o % do cronograma) | F31: 0.0126
B33: 5º passo: Executado do mês (incluir o % medido) | F33: 0.0159
B35: 6º passo: Previsto acumulado do mês | F35: 0.9832
B37: 7º passo: Executado acumulado do mês | F37: 0.9743
B39: 8º passo: Crédito do orçamento (executado acumulado × orçamento) | F39: =F37*J28 -> 21900861
B41: 8º passo (cont.): Saldo de contrato (tabela) | F41: =E74 -> 0
B43: 9º passo: Adiantamento de serviços não medidos (tabela) | F43: =E88 -> 0
B45: 10º passo: Adiantamento de materiais não estocados (tabela) | F45: =J74 -> 0
B47: 11º passo: Estoque de materiais (almoxarifado) | F47: =J88 -> 52715.27
B49: 12º passo: Equipamentos comprados (valor de mercado) | F49: =E102 -> 183300
B51: 13º passo: Receitas de personalizações (tabela) | F51: =J102 -> 592000
B53: 14º passo: Contas a pagar dos medidos (relatório a pagar) | F53: =E115 -> 83526.48
B55: 15º passo: Valor desembolsado pela obra (relatório conferido) | F55: 22138392
B56: Valor corrigido (sem os itens apontados irregularmente) | F56: =F55-J115 -> 22138392
B58: 16º passo: Dívida da obra a ser paga (outra obra da carteira) | F58: =E129 -> 0
B63: Saldo de contrato | G63: Adiantamento de materiais não estocados
B74: Total | E74: =SUM(E64:E73) -> 0 | G74: Total | J74: =SUM(J64:J73) -> 0
B77: Adiantamento de serviços não medidos | G77: Estoque de materiais
G78: Louças e metais de reposição | J78: 32865.15
G79: Tinta para retoques | J79: 19850.12
B88: Total | E88: =SUM(E78:E87) -> 0 | G88: Total | J88: =SUM(J78:J87) -> 52715.27
B91: Equipamentos comprados | G91: Receitas de personalizações
B92: Betoneira 400 L | E92: 9800 | G92: Unid. 501 · troca de piso da sala (cliente I. Moura) | J92: 75583
B93: Guincho de coluna | E93: 38500 | G93: Unid. 1603 · bancada da cozinha em quartzo (cliente J. Viana) | J93: 68382.04
B94: Andaime fachadeiro (lote) | E94: 64000 | G94: Unid. 401 · planta com home office (cliente K. Saraiva) | J94: 76892.69
B95: Plataforma elevatória | E95: 71000 | G95: Unid. 201 · ponto extra de ar-condicionado (cliente L. Fernandes) | J95: 62109.69
G96: Unid. 302 · revestimento da varanda (cliente M. Albuquerque) | J96: 51926.63
G97: Unid. 1302 · fechamento da cozinha (cliente N. Siqueira) | J97: 68393.62
G98: Unid. 1104 · box e metais de padrão superior (cliente A. Cavalcanti) | J98: 87781.44
...
